Workbook

Sheet Sheet2
A1: KBLI G
A3: Tanggal | B3: level_2_full_code | C3: level_6_full_code | D3: kategori_baru | E3: kode_kbli_baru | F3: nama_usaha | G3: Produk | H3: Kegiatan Utama | I3: metrik_biaya_produksi | J3: metrik_biaya_pembelian | K3: metrik_biaya_operasional | L3: metrik_biaya_non_operasional | M3: total_pengeluaran | N3: metrik_pendapatan_barang_jasa | O3: metrik_pendapatan_lainnya | P3: metrik_nilai_tambah | Q3: metrik_total_aset | R3: metrik_output | S3: rasio_biaya_pembelian_barang_terhadap_omzet | T3: rasio_ntb | U3: link_fasih_sm | V3: Kode Remark | W3: Tindak Lanjut Fasih | X3: biaya_operasional_baru | Y3: biaya_produksi_baru | Z3: kategori_baru | AA3: kode_kbli_baru | AB3: komentar | AC3: cek
A4: 46310 | B4: 5309 | C4: 5.30907e+15 | D4: G | E4: 47112 | F4: USAHA KIOS (NURHANI ABONG) | G4: SEMBAKO, ROKO, SNACK, SABUN MANDI, SABUN CUCI | H4: perdagangan enceran sembako | I4: 13000000 | J4: 0 | K4: 500000 | L4: 0 | M4: 13500000 | N4: 20000000 | O4: 0 | P4: 6500000 | Q4: 2000000 | R4: 20000000 | S4: 0 | T4: 0.325 | U4: https://fasih-sm.bps.go.id/app/assignment/fd68e454-ba45-4b85-8205-f3bf777ded24/0c5a5069-af0d-4f49-88e9-62e371a31303 | X4: 266667 | Y4: 6933333 | Z4: G | AA4: 47112 | AB4: #4 | AC4: =VLOOKUP(U4,Sheet1!$F$1:$F$39,1,FALSE) -> #N/A | AD4: =IF(ISNA(AC4),1,0) -> 1
A5: 46310 | B5: 5309 | C5: 5.309011e+15 | D5: G | E5: 47112 | F5: KIOS CALISTA | G5: Sembako | H5: Menjual sembako eceran di kios | I5: 20000000 | J5: 100000000 | K5: 10000000 | L5: 300000 | M5: 130300000 | N5: 166000000 | O5: 16000000 | P5: 36000000 | Q5: 13000000 | R5: 66000000 | S5: 0.60241 | T5: 0.545455 | U5: https://fasih-sm.bps.go.id/app/assignment/fd68e454-ba45-4b85-8205-f3bf777ded24/e6e22d92-52c2-4d20-85da-61a3c5d3decf | X5: 7920000 | Y5: 15840000 | Z5: G | AA5: 47112 | AB5: #4 | AC5: =VLOOKUP(U5,Sheet1!$F$1:$F$39,1,FALSE) -> #N/A | AD5: =IF(ISNA(AC5),1,0) -> 1
A6: 46310 | B6: 5309 | C6: 5.30904e+15 | D6: G | E6: 47112 | F6: USAHA PERDAGANGAN (MARTINA HOPILERA GAMUR) | G6: ECERAN SEMBAKO | H6: MENJUAL ECERAN SEMBAKO | I6: 0 | J6: 36000000 | K6: 1320000 | L6: 0 | M6: 37320000 | N6: 46920000 | O6: 0 | P6: 9600000 | Q6: 0 | R6: 10920000 | S6: 0.767263 | T6: 0.879121 | U6: https://fasih-sm.bps.go.id/app/assignment/fd68e454-ba45-4b85-8205-f3bf777ded24/f31c5b7f-d79f-4a86-b395-f981fa38f7e3 | X6: 2402400 | Y6: 0 | Z6: G | AA6: 47112 | AB6: #4 | AC6: =VLOOKUP(U6,Sheet1!$F$1:$F$39,1,FALSE) -> #N/A | AD6: =IF(ISNA(AC6),1,0) -> 1
A7: 46310 | B7: 5309 | C7: 5.30904e+15 | D7: G | E7: 47112 | F7: USAHA PERDAGANGAN (HENDRIKUS PATARAYA KOLIN) | G7: JAMBU METE | H7: MEMBUDIDAYAKAN TANAMAN PERKEBUNAN | I7: 0 | J7: 28800000 | K7: 0 | L7: 0 | M7: 0 | N7: 34800000 | O7: 0 | P7: 6000000 | Q7: 38200000 | R7: 6000000 | S7: 0.827586 | T7: 1 | U7: https://fasih-sm.bps.go.id/app/assignment/fd68e454-ba45-4b85-8205-f3bf777ded24/1e215243-5f26-4440-81c3-c5bbb8b51a06 | X7: 1320000 | Y7: 0 | Z7: G | AA7: 47112 | AB7: #4 | AC7: =VLOOKUP(U7,Sheet1!$F$1:$F$39,1,FALSE) -> #N/A | AD7: =IF(ISNA(AC7),1,0) -> 1
A8: 46310 | B8: 5309 | C8: 5.30907e+15 | D8: G | E8: 47112 | F8: KIOS ECERAN (AGUS SALIM) | G8: Makanan minuman eceran | H8: Menjual makanan minuman dan tembakau eceran di dalam rumah | I8: 100000 | J8: 22000000 | K8: 3000000 | L8: 500000 | M8: 25600000 | N8: 29000000 | O8: 0 | P8: 3900000 | Q8: 2500000 | R8: 7000000 | S8: 0.758621 | T8: 0.557143 | U8: https://fasih-sm.bps.go.id/app/assignment/fd68e454-ba45-4b85-8205-f3bf777ded24/213e3b07-2ba7-42e2-a01f-f3d81f84233f | X8: 2438710 | Y8: 81290 | Z8: G | AA8: 47112 | AB8: #4 | AC8: =VLOOKUP(U8,Sheet1!$F$1:$F$39,1,FALSE) -> #N/A | AD8: =IF(ISNA(AC8),1,0) -> 1
A9: 46310 | B9: 5309 | C9: 5.309062e+15 | D9: G | E9: 47112 | F9: USAHA KIOS SEMBAKO(MARTINA) | G9: BUAH KELAPA BULAT | H9: TANAM,RAWAT,PANEN DAN DI JUAL | I9: 300000 | J9: 10000000 | K9: 500000 | L9: 0 | M9: 1100000 | N9: 15000000 | O9: 0 | P9: 4200000 | Q9: 5400000 | R9: 5000000 | S9: 0.666667 | T9: 0.84 | U9: https://fasih-sm.bps.go.id/app/assignment/fd68e454-ba45-4b85-8205-f3bf777ded24/3b816d64-7a54-4b25-bb48-563c1725fa49 | X9: 687500 | Y9: 412500 | Z9: G | AA9: 47112 | AB9: #4 | AC9: =VLOOKUP(U9,Sheet1!$F$1:$F$39,1,FALSE) -> #N/A | AD9: =IF(ISNA(AC9),1,0) -> 1
A10: 46310 | B10: 5309 | C10: 5.30903e+15 | D10: G | E10: 47112 | F10: KIOS (BUNGA HULER) | G10: JAJANAN ECERAN | H10: MENJUAL SEMBAKO DAN JAJANAN ECERAN | I10: 0 | J10: 36000000 | K10: 4200000 | L10: 0 | M10: 3350000 | N10: 158400000 | O10: 0 | P10: 118200000 | Q10: 0 | R10: 122400000 | S10: 0.227273 | T10: 0.965686 | U10: https://fasih-sm.bps.go.id/app/assignment/fd68e454-ba45-4b85-8205-f3bf777ded24/2f5a774e-4d8b-4b0a-9d63-f951717ffd7b | X10: 26928000 | Y10: 0 | Z10: G | AA10: 47112 | AB10: #4 | AC10: =VLOOKUP(U10,Sheet1!$F$1:$F$39,1,FALSE) -> #N/A | AD10: =IF(ISNA(AC10),1,0) -> 1
A11: 46310 | B11: 5309 | C11: 5.309071e+15 | D11: G | E11: 47112 | F11: KIOS SEMBAKO (MAISAROH) | G11: Minyak goreng, telur, beras, mie dll | H11: Menjual sembako | I11: 0 | J11: 8000000 | K11: 900000 | L11: 0 | M11: 8900000 | N11: 9500000 | O11: 0 | P11: 600000 | Q11: 2800000 | R11: 1500000 | S11: 0.842105 | T11: 0.4 | U11: https://fasih-sm.bps.go.id/app/assignment/fd68e454-ba45-4b85-8205-f3bf777ded24/9b3773d8-b8bc-4231-bfaa-c8d777a7c8d6 | X11: 540000 | Y11: 0 | Z11: G | AA11: 47112 | AB11: #4 | AC11: =VLOOKUP(U11,Sheet1!$F$1:$F$39,1,FALSE) -> #N/A | AD11: =IF(ISNA(AC11),1,0) -> 1
A12: 46310 | B12: 5309 | C12: 5.30907e+15 | D12: G | E12: 47112 | F12: KIOS ( FATIMA ABDULLAH) | G12: Jajanan | H12: Menjual jajanan | I12: 100000 | J12: 24000000 | K12: 960000 | L12: 0 | M12: 25060000 | N12: 36000000 | O12: 0 | P12: 10940000 | Q12: 600000 | R12: 12000000 | S12: 0.666667 | T12: 0.911667 | U12: https://fasih-sm.bps.go.id/app/assignment/fd68e454-ba45-4b85-8205-f3bf777ded24/92e51f2d-5375-459b-b5bb-b075846eb6e9 | X12: 2390943 | Y12: 249057 | Z12: G | AA12: 47112 | AB12: #4 | AC12: =VLOOKUP(U12,Sheet1!$F$1:$F$39,1,FALSE) -> #N/A | AD12: =IF(ISNA(AC12),1,0) -> 1
A13: 46310 | B13: 5309 | C13: 5.309072e+15 | D13: G | E13: 47112 | F13: USAHA KIOS(KATARINA SURAT BALA) | G13: JAMBU METE | H13: MEMBUDIDAYAKAN TANAMAN JAMBU MENTE | I13: 1000000 | J13: 250000 | K13: 0 | L13: 0 | M13: 300000 | N13: 8000000 | O13: 0 | P13: 6750000 | Q13: 1000000 | R13: 7750000 | S13: 0.03125 | T13: 0.870968 | U13: https://fasih-sm.bps.go.id/app/assignment/fd68e454-ba45-4b85-8205-f3bf777ded24/7b4f943a-5b15-4053-b728-96ad994ed715 | X13: 0 | Y13: 1705000 | Z13: G | AA13: 47112 | AB13: #4 | AC13: =VLOOKUP(U13,Sheet1!$F$1:$F$39,1,FALSE) -> #N/A | AD13: =IF(ISNA(AC13),1,0) -> 1
A14: 46310 | B14: 5309 | C14: 5.30905e+15 | D14: G | E14: 47112 | F14: KIOS SEMBAKO(MUSLIMIN GAFUR) | G14: DAUN LONTAR | H14: KUAL BELI DAUN LONTAR | I14: 0 | J14: 14000000 | K14: 100000 | L14: 0 | M14: 15000000 | N14: 18000000 | O14: 0 | P14: 3900000 | Q14: 7400000 | R14: 4000000 | S14: 0.777778 | T14: 0.975 | U14: https://fasih-sm.bps.go.id/app/assignment/fd68e454-ba45-4b85-8205-f3bf777ded24/b4cead52-469c-43b0-b85e-01f8ff49d8e5 | X14: 880000 | Y14: 0 | Z14: G | AA14: 47112 | AB14: #4 | AC14: =VLOOKUP(U14,Sheet1!$F$1:$F$39,1,FALSE) -> #N/A | AD14: =IF(ISNA(AC14),1,0) -> 1
A15: 46310 | B15: 5309 | C15: 5.309073e+15 | D15: G | E15: 47112 | F15: KIOS (LUKMAN BUGA SENARI) | G15: Barang makanan dan non makanan | H15: Menjual barang makanan dan non makanan | I15: 0 | J15: 60000000 | K15: 600000 | L15: 0 | M15: 60600000 | N15: 108000000 | O15: 0 | P15: 47400000 | Q15: 12500000 | R15: 48000000 | S15: 0.555556 | T15: 0.9875 | U15: https://fasih-sm.bps.go.id/app/assignment/fd68e454-ba45-4b85-8205-f3bf777ded24/c6050d89-ea90-44cc-aa48-559b89e0c1d4 | X15: 10560000 | Y15: 0 | Z15: G | AA15: 47112 | AB15: #4 | AC15: =VLOOKUP(U15,Sheet1!$F$1:$F$39,1,FALSE) -> #N/A | AD15: =IF(ISNA(AC15),1,0) -> 1
... A41: 46310 | B41: 5309 | C41: 5.309073e+15 | D41: G | E41: 47301 | F41: JASA PERDAGANGAN BENSIN ECERAN(SARIMA MASUD) | G41: KELAPA | H41: BUDIDAYA TANAMAN KELAPA | I41: 0 | J41: 48000000 | K41: 0 | L41: 0 | M41: 1750000 | N41: 48480000 | O41: 0 | P41: 480000 | Q41: 5780000 | R41: 480000 | S41: 0.990099 | T41: 1 | U41: https://fasih-sm.bps.go.id/app/assignment/fd68e454-ba45-4b85-8205-f3bf777ded24/e235d7a9-cb9f-4ac4-8a7b-b07d6f92538b | X41: 105600 | Y41: 0 | Z41: G | AA41: 47301 | AB41: #4 | AC41: =VLOOKUP(U41,Sheet1!$F$1:$F$39,1,FALSE) -> https://fasih-sm.bps.go.id/app/assignment/fd68e454-ba45-4b85-8205-f3bf777ded24/e235d7a9-cb9f-4ac4-8a7b-b07d6f92538b | AD41: =IF(ISNA(AC41),1,0) -> 0
A42: 46310 | B42: 5309 | D42: G | E42: 47301 | F42: KUD MINA GONSALU RAYA | I42: 30000000 | J42: 9380927103 | K42: 46600000 | L42: 19686136 | N42: 9954268400 | O42: 0 | P42: 496741297 | Q42: 569000000 | R42: 573341297 | S42: 0.942402 | T42: 0.866397 | U42: https://fasih-sm.bps.go.id/app/assignment/fd68e454-ba45-4b85-8205-f3bf777ded24/144ed904-d0bf-4477-b284-c92cc8afe676 | X42: 76734922 | Y42: 49400164 | Z42: G | AA42: 47301 | AB42: #4 | AC42: =VLOOKUP(U42,Sheet1!$F$1:$F$39,1,FALSE) -> https://fasih-sm.bps.go.id/app/assignment/fd68e454-ba45-4b85-8205-f3bf777ded24/144ed904-d0bf-4477-b284-c92cc8afe676 | AD42: =IF(ISNA(AC42),1,0) -> 0
A43: 46310 | B43: 5309 | C43: 5.30905e+15 | D43: G | E43: 47302 | F43: JUAL BENSIN (MANSUR BAHRUDIN) | G43: PISANG NUGGET DAN KLEPON | H43: MEMBUAT DAN MENJUAL KUE | I43: 2000000 | J43: 6720000 | K43: 1000000 | L43: 0 | M43: 4300000 | N43: 12720000 | O43: 0 | P43: 3000000 | Q43: 300000 | R43: 6000000 | S43: 0.528302 | T43: 0.5 | U43: https://fasih-sm.bps.go.id/app/assignment/fd68e454-ba45-4b85-8205-f3bf777ded24/8caa52a3-7d04-49a9-9947-afb518886978 | X43: 720000 | Y43: 1440000 | Z43: G | AA43: 47302 | AB43: #4 | AC43: =VLOOKUP(U43,Sheet1!$F$1:$F$39,1,FALSE) -> #N/A | AD43: =IF(ISNA(AC43),1,0) -> 1
A44: 46310 | B44: 5309 | C44: 5.30904e+15 | D44: G | E44: 47302 | F44: USAHA PERDAGANGAN (MENSI KEBAN) | G44: ECERAN BENSIN | H44: MENJUAL ECERAN BENSIN | I44: 0 | J44: 4830000 | K44: 20000 | L44: 0 | M44: 4850000 | N44: 6596000 | O44: 0 | P44: 1746000 | Q44: 25000000 | R44: 1766000 | S44: 0.732262 | T44: 0.988675 | U44: https://fasih-sm.bps.go.id/app/assignment/fd68e454-ba45-4b85-8205-f3bf777ded24/bd7ffe31-3900-4c35-b87f-ee76b3436a15 | X44: 388520 | Y44: 0 | Z44: G | AA44: 47302 | AB44: #4 | AC44: =VLOOKUP(U44,Sheet1!$F$1:$F$39,1,FALSE) -> #N/A | AD44: =IF(ISNA(AC44),1,0) -> 1
A45: 46310 | B45: 5309 | C45: 5.30904e+15 | D45: G | E45: 47302 | F45: USAHA PERDAGANGAN (MAXIMILIANUS KEWANI TUKAN) | G45: JAGUNG LOKAL | H45: MENBUDIDAYAKAN TANAMAN JAGUNG | I45: 0 | J45: 141120000 | K45: 5760000 | L45: 0 | M45: 1105000 | N45: 151200000 | O45: 0 | P45: 4320000 | Q45: 0 | R45: 10080000 | S45: 0.933333 | T45: 0.428571 | U45: https://fasih-sm.bps.go.id/app/assignment/fd68e454-ba45-4b85-8205-f3bf777ded24/9ed9c363-fce6-48da-bd02-83c176b005de | X45: 3628800 | Y45: 0 | Z45: G | AA45: 47302 | AB45: #4 | AC45: =VLOOKUP(U45,Sheet1!$F$1:$F$39,1,FALSE) -> https://fasih-sm.bps.go.id/app/assignment/fd68e454-ba45-4b85-8205-f3bf777ded24/9ed9c363-fce6-48da-bd02-83c176b005de | AD45: =IF(ISNA(AC45),1,0) -> 0
A46: 46310 | B46: 5309 | C46: 5.30903e+15 | D46: G | E46: 47302 | F46: PEDAGANG MINYAK ECERAN SNURI LEWAR | G46: Solar, minyak tanah, pertalite | H46: Penjualan minyak eceran | I46: 200000 | J46: 45000000 | K46: 2000000 | L46: 0 | M46: 47200000 | N46: 56000000 | O46: 0 | P46: 8800000 | Q46: 85000000 | R46: 11000000 | S46: 0.803571 | T46: 0.8 | U46: https://fasih-sm.bps.go.id/app/assignment/fd68e454-ba45-4b85-8205-f3bf777ded24/042f84a9-9588-4867-b8dd-a2e5fefcaca1 | X46: 2200000 | Y46: 220000 | Z46: G | AA46: 47302 | AB46: #4 | AC46: =VLOOKUP(U46,Sheet1!$F$1:$F$39,1,FALSE) -> #N/A | AD46: =IF(ISNA(AC46),1,0) -> 1
A47: 46310 | B47: 5309 | C47: 5.309061e+15 | D47: G | E47: 47302 | F47: JUAL BENSIN ECERAN | G47: BABI | H47: PENGEMBANGBIAKAN | I47: 0 | J47: 11000000 | K47: 0 | L47: 0 | M47: 6000000 | N47: 12000000 | O47: 0 | P47: 1000000 | Q47: 300000 | R47: 1000000 | S47: 0.916667 | T47: 1 | U47: https://fasih-sm.bps.go.id/app/assignment/fd68e454-ba45-4b85-8205-f3bf777ded24/c7c36ece-b8d0-4c49-91aa-db05b8ce7d9b | X47: 220000 | Y47: 0 | Z47: G | AA47: 47302 | AB47: #4 | AC47: =VLOOKUP(U47,Sheet1!$F$1:$F$39,1,FALSE) -> #N/A | AD47: =IF(ISNA(AC47),1,0) -> 1
A48: 46310 | B48: 5309 | C48: 5.309071e+15 | D48: G | E48: 47511 | F48: JUAL KAIN ( KRISTINA PENATEN BEDA ) | G48: Kain sarung | H48: Penjualan kain sarung | I48: 0 | J48: 48000000 | K48: 3000000 | L48: 0 | M48: 51000000 | N48: 54000000 | O48: 0 | P48: 3000000 | Q48: 3000000 | R48: 6000000 | S48: 0.888889 | T48: 0.5 | U48: https://fasih-sm.bps.go.id/app/assignment/fd68e454-ba45-4b85-8205-f3bf777ded24/c3b5f6af-1910-4ba8-b7de-afb16c8ce7e2 | X48: 2160000 | Y48: 0 | Z48: G | AA48: 47511 | AB48: #4 | AC48: =VLOOKUP(U48,Sheet1!$F$1:$F$39,1,FALSE) -> https://fasih-sm.bps.go.id/app/assignment/fd68e454-ba45-4b85-8205-f3bf777ded24/c3b5f6af-1910-4ba8-b7de-afb16c8ce7e2 | AD48: =IF(ISNA(AC48),1,0) -> 0
A49: 46310 | B49: 5309 | C49: 5.30905e+15 | D49: G | E49: 47521 | F49: PEMASOK MATERIAL (KHAIRUL ABIDIN) | G49: SEMEN, SENG, BESI DAN LAINNYA | H49: MENJUAL BAHAN BANGUNAN | I49: 8000000 | J49: 900000000 | K49: 2000000 | L49: 0 | M49: 922000000 | N49: 970000000 | O49: 0 | P49: 60000000 | Q49: 51800000 | R49: 70000000 | S49: 0.927835 | T49: 0.857143 | U49: https://fasih-sm.bps.go.id/app/assignment/fd68e454-ba45-4b85-8205-f3bf777ded24/9ce56cb9-f347-4bfa-a5f0-cfece604421f | X49: 3080000 | Y49: 12320000 | Z49: G | AA49: 47521 | AB49: #4 | AC49: =VLOOKUP(U49,Sheet1!$F$1:$F$39,1,FALSE) -> #N/A | AD49: =IF(ISNA(AC49),1,0) -> 1
A50: 46310 | B50: 5309 | C50: 5.30903e+15 | D50: G | E50: 47711 | F50: KIOS PAKAIAN 1 (RIZAL) | G50: Menjual pakaian | H50: Menjual pakaian | I50: 200000 | J50: 40000000 | K50: 2200000 | L50: 700000 | M50: 54620000 | N50: 93600000 | O50: 0 | P50: 51200000 | Q50: 50000000 | R50: 53600000 | S50: 0.42735 | T50: 0.955224 | U50: https://fasih-sm.bps.go.id/app/assignment/fd68e454-ba45-4b85-8205-f3bf777ded24/e56bccfc-852f-4d12-8c93-34d4005cee89 | X50: 10809333 | Y50: 982667 | Z50: G | AA50: 47711 | AB50: #4 | AC50: =VLOOKUP(U50,Sheet1!$F$1:$F$39,1,FALSE) -> #N/A | AD50: =IF(ISNA(AC50),1,0) -> 1
A51: 46310 | B51: 5309 | C51: 5.30903e+15 | D51: G | E51: 47711 | F51: KIOS PAKAIAN ASSIFA (FATCHUL MUNIF) | G51: Menjual pakain | H51: Menjual pakaian jadi | I51: 90000 | J51: 40000000 | K51: 600000 | L51: 1080000 | M51: 41770000 | N51: 62400000 | O51: 0 | P51: 21710000 | Q51: 30000000 | R51: 22400000 | S51: 0.641026 | T51: 0.969196 | U51: https://fasih-sm.bps.go.id/app/assignment/fd68e454-ba45-4b85-8205-f3bf777ded24/fc193fcf-736d-421f-ac1a-cfd60653a3e8 | X51: 4285217 | Y51: 642783 | Z51: G | AA51: 47711 | AB51: #4 | AC51: =VLOOKUP(U51,Sheet1!$F$1:$F$39,1,FALSE) -> #N/A | AD51: =IF(ISNA(AC51),1,0) -> 1
A52: 46310 | B52: 5309 | C52: 5.30903e+15 | D52: G | E52: 47711 | F52: KIOS PAKAIAN & PARFUM (RIZKA) | G52: Menjual Pakaian dan parfum | H52: Menjual Pakaian dan parfum | I52: 160000 | J52: 60000000 | K52: 300000 | L52: 1704000 | M52: 62164000 | N52: 86164000 | O52: 0 | P52: 25704000 | Q52: 50000000 | R52: 26164000 | S52: 0.696347 | T52: 0.982419 | U52: https://fasih-sm.bps.go.id/app/assignment/fd68e454-ba45-4b85-8205-f3bf777ded24/a151b224-a1b1-47f0-9e57-db0216935331 | X52: 3753965 | Y52: 2002115 | Z52: G | AA52: 47711 | AB52: #4 | AC52: =VLOOKUP(U52,Sheet1!$F$1:$F$39,1,FALSE) -> #N/A | AD52: =IF(ISNA(AC52),1,0) -> 1
A53: 46310 | B53: 5309 | C53: 5.309074e+15 | D53: G | E53: 47711 | F53: USAHA JUAL PAKAIAN | G53: BUSANA | H53: MENJUAL BERBAGAI JENIS BUSANA | I53: 150000 | J53: 3000000 | K53: 250000 | L53: 0 | M53: 3400000 | N53: 12000000 | O53: 0 | P53: 8600000 | Q53: 1100000 | R53: 9000000 | S53: 0.25 | T53: 0.955556 | U53: https://fasih-sm.bps.go.id/app/assignment/fd68e454-ba45-4b85-8205-f3bf777ded24/32b7419a-ac1e-4ba6-8894-51ac0548fe11 | X53: 1237500 | Y53: 742500 | Z53: G | AA53: 47711 | AB53: #4 | AC53: =VLOOKUP(U53,Sheet1!$F$1:$F$39,1,FALSE) -> #N/A | AD53: =IF(ISNA(AC53),1,0) -> 1
A54: 46310 | B54: 5309 | C54: 5.30903e+15 | D54: G | E54: 47711 | F54: MIATI FASHION (YUSRAN) | G54: Menjual pakaian | H54: Menjual pakaian | I54: 240000 | J54: 12000000 | K54: 2400000 | L54: 4400000 | M54: 19040000 | N54: 30000000 | O54: 0 | P54: 15360000 | Q54: 50000000 | R54: 18000000 | S54: 0.4 | T54: 0.853333 | U54: https://fasih-sm.bps.go.id/app/assignment/fd68e454-ba45-4b85-8205-f3bf777ded24/814b8915-3c7f-49e4-82c4-2421d54370d1 | X54: 3600000 | Y54: 360000 | Z54: G | AA54: 47711 | AB54: #4 | AC54: =VLOOKUP(U54,Sheet1!$F$1:$F$39,1,FALSE) -> #N/A | AD54: =IF(ISNA(AC54),1,0) -> 1
... A145: 46310 | B145: 5309 | C145: 5.30907e+15 | D145: G | E145: 47111 | F145: KIOS (MONIKA PENI MASAN) | G145: Jajan, sembako, tembakau | H145: Menjual jajanan, sembako, dan tembakau | I145: 50000 | J145: 28000000 | K145: 300000 | L145: 0 | M145: 28350000 | N145: 45000000 | O145: 0 | P145: 16650000 | Q145: 3100000 | R145: 17000000 | S145: 0.622222 | T145: 0.979412 | U145: https://fasih-sm.bps.go.id/app/assignment/fd68e454-ba45-4b85-8205-f3bf777ded24/4485e691-ef32-4be3-be08-3094d892946d | X145: 3205714 | Y145: 534286 | Z145: G | AA145: 47111 | AB145: #4 | AC145: =VLOOKUP(U145,Sheet1!$F$1:$F$39,1,FALSE) -> #N/A | AD145: =IF(ISNA(AC145),1,0) -> 1
A146: 46310 | B146: 5309 | D146: G | E146: 47112 | F146: KIOS SEMBAKO DUA PUTRA (NURASIAH) | I146: 0 | J146: 300000000 | K146: 26900000 | L146: 0 | N146: 625000000 | O146: 0 | P146: 298100000 | Q146: 380000000 | R146: 325000000 | S146: 0.48 | T146: 0.917231 | U146: https://fasih-sm.bps.go.id/app/assignment/fd68e454-ba45-4b85-8205-f3bf777ded24/120f458c-61b4-4f31-9c2e-1f1e444b6302 | X146: 71500000 | Y146: 0 | Z146: G | AA146: 47112 | AB146: #4 | AC146: =VLOOKUP(U146,Sheet1!$F$1:$F$39,1,FALSE) -> https://fasih-sm.bps.go.id/app/assignment/fd68e454-ba45-4b85-8205-f3bf777ded24/120f458c-61b4-4f31-9c2e-1f1e444b6302 | AD146: =IF(ISNA(AC146),1,0) -> 0
A147: 46310 | B147: 5309 | C147: 5.309041e+15 | D147: G | E147: 47112 | F147: USAHA KIOS SEMBAKO (KATARINA PENI WUJON) | G147: BARANG SEMBAKO | H147: JUAL BELI BARANG SEMBAKO | I147: 500000 | J147: 0 | K147: 1000000 | L147: 0 | M147: 1500000 | N147: 4000000 | O147: 0 | P147: 2500000 | Q147: 1500000 | R147: 4000000 | S147: 0 | T147: 0.625 | U147: https://fasih-sm.bps.go.id/app/assignment/fd68e454-ba45-4b85-8205-f3bf777ded24/147d2d50-d706-4e6c-a7a8-4fec51568715 | X147: 960000 | Y147: 480000 | Z147: G | AA147: 47112 | AB147: #4 | AC147: =VLOOKUP(U147,Sheet1!$F$1:$F$39,1,FALSE) -> #N/A | AD147: =IF(ISNA(AC147),1,0) -> 1
A148: 46310 | B148: 5309 | C148: 5.30903e+15 | D148: G | E148: 47112 | F148: KIOS LENY | G148: Eceran Sembako | H148: Kios jualan eceran sembako | I148: 200000 | J148: 600000 | K148: 0 | L148: 0 | M148: 800000 | N148: 2500000 | O148: 0 | P148: 1700000 | Q148: 0 | R148: 1900000 | S148: 0.24 | T148: 0.894737 | U148: https://fasih-sm.bps.go.id/app/assignment/fd68e454-ba45-4b85-8205-f3bf777ded24/934fdab2-b3b5-448c-be73-20de34ed5d7b | X148: 0 | Y148: 418000 | Z148: G | AA148: 47112 | AB148: #4 | AC148: =VLOOKUP(U148,Sheet1!$F$1:$F$39,1,FALSE) -> #N/A | AD148: =IF(ISNA(AC148),1,0) -> 1
A149: 46310 | B149: 5309 | C149: 5.30907e+15 | D149: G | E149: 47112 | F149: KIOS SEMBAKO (DAHLIA ALI) | G149: SEMBAKO DAN LAINNYA | H149: MENJUAL KEBUTUHAN POKOK DAN KEPRLUAN LAINNYA | I149: 1750000 | J149: 144000000 | K149: 1560000 | L149: 0 | M149: 147310000 | N149: 180000000 | O149: 0 | P149: 32690000 | Q149: 45000000 | R149: 36000000 | S149: 0.8 | T149: 0.908056 | U149: https://fasih-sm.bps.go.id/app/assignment/fd68e454-ba45-4b85-8205-f3bf777ded24/905cfed2-b769-40cb-9450-500e08feca56 | X149: 3732689 | Y149: 4187311 | Z149: G | AA149: 47112 | AB149: #4 | AC149: =VLOOKUP(U149,Sheet1!$F$1:$F$39,1,FALSE) -> #N/A | AD149: =IF(ISNA(AC149),1,0) -> 1
A150: 46310 | B150: 5309 | C150: 5.309062e+15 | D150: G | E150: 47112 | F150: USAHA KIOS | G150: PISANG KEPOK | H150: BUDIDAYA TANAMAN PISANG KEPOK | I150: 100000 | J150: 1000000 | K150: 500000 | L150: 0 | M150: 400000 | N150: 6000000 | O150: 0 | P150: 4400000 | Q150: 4200000 | R150: 5000000 | S150: 0.166667 | T150: 0.88 | U150: https://fasih-sm.bps.go.id/app/assignment/fd68e454-ba45-4b85-8205-f3bf777ded24/d123e948-3235-46b1-b021-28518d1321e3 | X150: 916667 | Y150: 183333 | Z150: G | AA150: 47112 | AB150: #4 | AC150: =VLOOKUP(U150,Sheet1!$F$1:$F$39,1,FALSE) -> #N/A | AD150: =IF(ISNA(AC150),1,0) -> 1
A151: 46310 | B151: 5309 | C151: 5.30903e+15 | D151: G | E151: 47112 | F151: KIOS ERLEN | G151: Sembako | H151: menjual sarimie, telur, rokok | I151: 3000000 | J151: 0 | K151: 0 | L151: 0 | M151: 3000000 | N151: 7000000 | O151: 0 | P151: 4000000 | Q151: 0 | R151: 7000000 | S151: 0 | T151: 0.571429 | U151: https://fasih-sm.bps.go.id/app/assignment/fd68e454-ba45-4b85-8205-f3bf777ded24/e1b51513-4b0b-44ca-bb06-477e3a9e9624 | X151: 0 | Y151: 2520000 | Z151: G | AA151: 47112 | AB151: #4 | AC151: =VLOOKUP(U151,Sheet1!$F$1:$F$39,1,FALSE) -> #N/A | AD151: =IF(ISNA(AC151),1,0) -> 1
A152: 46310 | B152: 5309 | C152: 5.309072e+15 | D152: G | E152: 47112 | F152: KIOS OSE BALE (OSE BALE) | G152: Sembako | H152: Jualan Aneka Sembako | I152: 120000 | J152: 5000000 | K152: 200000 | L152: 18000 | M152: 5338000 | N152: 8000000 | O152: 0 | P152: 2680000 | Q152: 25000000 | R152: 3000000 | S152: 0.625 | T152: 0.893333 | U152: https://fasih-sm.bps.go.id/app/assignment/fd68e454-ba45-4b85-8205-f3bf777ded24/dd38301a-428e-4c43-97b1-920efbd23b01 | X152: 412500 | Y152: 247500 | Z152: G | AA152: 47112 | AB152: #4 | AC152: =VLOOKUP(U152,Sheet1!$F$1:$F$39,1,FALSE) -> #N/A | AD152: =IF(ISNA(AC152),1,0) -> 1
A153: 46310 | B153: 5309 | C153: 5.30905e+15 | D153: G | E153: 47112 | F153: KIOS SEMBAKO (LASARUS GULA OPUN HULER) | G153: Sembako | H153: Menjual Sembako | I153: 0 | J153: 250000000 | K153: 2500000 | L153: 1500000 | M153: 259000000 | N153: 480000000 | O153: 0 | P153: 227500000 | Q153: 8000000 | R153: 230000000 | S153: 0.520833 | T153: 0.98913 | U153: https://fasih-sm.bps.go.id/app/assignment/fd68e454-ba45-4b85-8205-f3bf777ded24/04e8469a-7281-4143-883f-460bc88a93a3 | X153: 50600000 | Y153: 0 | Z153: G | AA153: 47112 | AB153: #4 | AC153: =VLOOKUP(U153,Sheet1!$F$1:$F$39,1,FALSE) -> #N/A | AD153: =IF(ISNA(AC153),1,0) -> 1
A154: 46310 | B154: 5309 | C154: 5.30905e+15 | D154: G | E154: 47112 | F154: JUAL GARAM LOKAL (JOHOR) | G154: Ikan | H154: Menangkap ikan konsumsi | I154: 200000 | J154: 4000000 | K154: 0 | L154: 500000 | M154: 1600000 | N154: 6000000 | O154: 0 | P154: 1800000 | Q154: 0 | R154: 2000000 | S154: 0.666667 | T154: 0.9 | U154: https://fasih-sm.bps.go.id/app/assignment/fd68e454-ba45-4b85-8205-f3bf777ded24/06964471-82b9-4abb-b4c1-1c15e2094a3c | X154: 0 | Y154: 440000 | Z154: G | AA154: 47112 | AB154: #4 | AC154: =VLOOKUP(U154,Sheet1!$F$1:$F$39,1,FALSE) -> #N/A | AD154: =IF(ISNA(AC154),1,0) -> 1
A155: 46310 | B155: 5309 | C155: 5.30903e+15 | D155: G | E155: 47112 | F155: KIOS WATO EKOT | G155: Sembako | H155: Menjual sembako | I155: 8750000 | J155: 7750000 | K155: 1000000 | L155: 350000 | M155: 17850000 | N155: 21670000 | O155: 0 | P155: 4170000 | Q155: 7200001 | R155: 13920000 | S155: 0.357637 | T155: 0.299569 | U155: https://fasih-sm.bps.go.id/app/assignment/fd68e454-ba45-4b85-8205-f3bf777ded24/4c01fdb4-f383-4f1d-8fef-c66a85abe708 | X155: 513969 | Y155: 4497231 | Z155: G | AA155: 47112 | AB155: #4 | AC155: =VLOOKUP(U155,Sheet1!$F$1:$F$39,1,FALSE) -> #N/A | AD155: =IF(ISNA(AC155),1,0) -> 1
A156: 46310 | B156: 5309 | C156: 5.309031e+15 | D156: G | E156: 47112 | F156: USAHA KIOS ( YANTO B. ARNOLDUSAMO ) | G156: PADI LADANG INBRIDA | H156: MEMBUDIDAYAKAN TANAMAN PANGAN UNTUK DIKONSUMSI SENDIRI | I156: 360000 | J156: 130000000 | K156: 360000 | L156: 5000 | M156: 255000 | N156: 156000000 | O156: 0 | P156: 25280000 | Q156: 55000000 | R156: 26000000 | S156: 0.833333 | T156: 0.972308 | U156: https://fasih-sm.bps.go.id/app/assignment/fd68e454-ba45-4b85-8205-f3bf777ded24/209e3a00-77d7-4b07-b64f-e6c67c49d5d9 | X156: 2860000 | Y156: 2860000 | Z156: G | AA156: 47112 | AB156: #4 | AC156: =VLOOKUP(U156,Sheet1!$F$1:$F$39,1,FALSE) -> #N/A | AD156: =IF(ISNA(AC156),1,0) -> 1
...

Sheet Sheet1
A1: baris | B1: nama_usaha | C1: assignment | D1: status | E1: alasan | F1: link
A2: 33 | B2: ARAK ( NATHAN KOSMAS) | C2: 3d6a943b | D2: KELEWAT-BULK | E2: tidak tercatat OK/GAGAL di bulk-repair â€” jalankan bulk-repair --resume | F2: https://fasih-sm.bps.go.id/app/assignment/fd68e454-ba45-4b85-8205-f3bf777ded24/8b5fb992-1edd-40b5-ad7c-990dc78fe0a9
A3: 41 | B3: JASA PERDAGANGAN BENSIN ECERAN(SARIMA MASUD) | C3: e235d7a9 | D3: REPAIR-GAGAL | E3: presign-url (s3/edit) gagal: No access for assignment 5309073006000600 - DTSEN - 7 (e235d7a9-cb9f-4ac4-8a7b-b0 | F3: https://fasih-sm.bps.go.id/app/assignment/fd68e454-ba45-4b85-8205-f3bf777ded24/e235d7a9-cb9f-4ac4-8a7b-b07d6f92538b
A4: 42 | B4: KUD MINA GONSALU RAYA | C4: 144ed904 | D4: REPAIR-GAGAL | E4: GET https://fasih-sm.bps.go.id/app/api/assignment-general/api/assignment-history/get-by-assignment-id -> HTTP | F4: https://fasih-sm.bps.go.id/app/assignment/fd68e454-ba45-4b85-8205-f3bf777ded24/144ed904-d0bf-4477-b284-c92cc8afe676
A5: 45 | B5: USAHA PERDAGANGAN (MAXIMILIANUS KEWANI TUKAN) | C5: 9ed9c363 | D5: REPAIR-GAGAL | E5: presign-url (s3/edit) gagal: No access for assignment 5309040010001100 - MAXIMILIANUS KEWANI KOLIN / ANTONIA S | F5: https://fasih-sm.bps.go.id/app/assignment/fd68e454-ba45-4b85-8205-f3bf777ded24/9ed9c363-fce6-48da-bd02-83c176b005de
A6: 48 | B6: JUAL KAIN ( KRISTINA PENATEN BEDA ) | C6: c3b5f6af | D6: REPAIR-GAGAL | E6: presign-url (s3/edit) gagal: No access for assignment 5309071006001800 - BANGUNAN KOSONG - 8 / (c3b5f6af-1910 | F6: https://fasih-sm.bps.go.id/app/assignment/fd68e454-ba45-4b85-8205-f3bf777ded24/c3b5f6af-1910-4ba8-b7de-afb16c8ce7e2
A7: 55 | B7: KIOS SENDAL SEPATU (ABDUL AZIZ 3) | C7: 98de06b9 | D7: KELEWAT-BULK | E7: tidak tercatat OK/GAGAL di bulk-repair â€” jalankan bulk-repair --resume | F7: https://fasih-sm.bps.go.id/app/assignment/fd68e454-ba45-4b85-8205-f3bf777ded24/f1481da1-eed2-44a2-8ea6-c51e29dda667
A8: 60 | B8: USAHA MINYAK TANAH (MARIA GEMA) | C8: 4f3ee94b | D8: REPAIR-GAGAL | E8: presign-url (s3/edit) gagal: No access for assignment 5309070058000300 - PETRUS SELI TUPEN / MARIA GEMA GALGAN | F8: https://fasih-sm.bps.go.id/app/assignment/fd68e454-ba45-4b85-8205-f3bf777ded24/4f3ee94b-12d4-4792-8b75-de1d8d9d909a
A9: 69 | B9: KIOS NAFATA(MASITAH MAS'UD) | C9: 41ee4c1a | D9: REPAIR-GAGAL | E9: presign-url (s3/edit) gagal: No access for assignment 5309073001001400 - DTSEN - 3 (41ee4c1a-9b06-4da2-8eaf-96 | F9: https://fasih-sm.bps.go.id/app/assignment/fd68e454-ba45-4b85-8205-f3bf777ded24/41ee4c1a-9b06-4da2-8eaf-966ae274050a
A10: 101 | B10: PERDAGANGAN ECERAN KELILING GARAM NON YODIUM GERSIANA PENI WOTAN | C10: c0f06105 | D10: REPAIR-GAGAL | E10: presign-url (s3/edit) gagal: No access for assignment 5309011006000200 - DTSEN - 21 (c0f06105-c947-45ca-b1d5-b | F10: https://fasih-sm.bps.go.id/app/assignment/fd68e454-ba45-4b85-8205-f3bf777ded24/c0f06105-c947-45ca-b1d5-b4c444091903
A11: 103 | B11: PERDAGANGAN | C11: 15218b8f | D11: REPAIR-GAGAL | E11: presign-url (s3/edit) gagal: No access for assignment 5309011007000200 - DTSEN - 8 (15218b8f-17f6-42ce-967b-21 | F11: https://fasih-sm.bps.go.id/app/assignment/fd68e454-ba45-4b85-8205-f3bf777ded24/15218b8f-17f6-42ce-967b-21c29ef48b7d
A12: 104 | B12: KIOS YUSRIL RATE IKEN | C12: 49258a06 | D12: REPAIR-GAGAL | E12: presign-url (s3/edit) gagal: No access for assignment 5309073010001000 - KIOS YUSRIL RATE IKEN - 25 / - 1 - 8 | F12: https://fasih-sm.bps.go.id/app/assignment/fd68e454-ba45-4b85-8205-f3bf777ded24/49258a06-f360-484b-a969-ec50d80b0d11
A13: 105 | B13: KIOS MANDIRI ( PHILOMENA ) | C13: f487e0bd | D13: KELEWAT-BULK | E13: tidak tercatat OK/GAGAL di bulk-repair â€” jalankan bulk-repair --resume | F13: https://fasih-sm.bps.go.id/app/assignment/fd68e454-ba45-4b85-8205-f3bf777ded24/68a4ee26-57a3-41d5-a67c-118da776514c
... A39: 270 | B39: USAHA JUAL ALAT MANCING (MARIA GORAN) | C39: 9aef6c6c | D39: REPAIR-GAGAL | E39: Respons bukan JSON dari https://fasih-sm.bps.go.id/app/api/assignment-submit/api/assignment/s3/edit: <!DOCTYPE | F39: https://fasih-sm.bps.go.id/app/assignment/fd68e454-ba45-4b85-8205-f3bf777ded24/9aef6c6c-c0f0-4d95-b3f3-28606de56cbe
